{"message": "Error in call to GetGeneralMerchant: TypeError(\"__init__() missing 1 required positional argument: 'self'\")", "level": "ERROR", "name": "merchant-service", "time": "2020-06-04T12:43:22.473637", "request": "merchantID: \"23034\"\n", "rollbar_uuid": "66e7a2a3-0e1d-45c9-b1a2-f43fbd9fcb63", "traceback": "Traceback (most recent call last):\n  File \"/Users/noah/Otis/backend/service/lib/utils/wrappers.py\", line 17, in wrap\n    return_value = func(*args, **kwargs)\n  File \"./impl/__init__.py\", line 39, in GetGeneralMerchant\n    m = Merchant()\n  File \"<string>\", line 4, in __init__\n  File \"/Users/noah/Otis/backend/service/merchant/merchant-service-venv/lib/python3.7/site-packages/sqlalchemy/orm/state.py\", line 433, in _initialize_instance\n    manager.dispatch.init_failure(self, args, kwargs)\n  File \"/Users/noah/Otis/backend/service/merchant/merchant-service-venv/lib/python3.7/site-packages/sqlalchemy/util/langhelpers.py\", line 69, in __exit__\n    exc_value, with_traceback=exc_tb,\n  File \"/Users/noah/Otis/backend/service/merchant/merchant-service-venv/lib/python3.7/site-packages/sqlalchemy/util/compat.py\", line 178, in raise_\n    raise exception\n  File \"/Users/noah/Otis/backend/service/merchant/merchant-service-venv/lib/python3.7/site-packages/sqlalchemy/orm/state.py\", line 430, in _initialize_instance\n    return manager.original_init(*mixed[1:], **kwargs)\n  File \"/Users/noah/Otis/backend/service/lib/psql/schemas/merchant.py\", line 16, in __init__\n    AddressMixin.__init__(nullable=False)\nTypeError: __init__() missing 1 required positional argument: 'self'\n"}
{"message": "Error in call to GetGeneralMerchant: TypeError(\"__init__() missing 1 required positional argument: 'self'\")", "level": "ERROR", "name": "merchant-service", "time": "2020-06-04T12:43:50.472934", "request": "merchantID: \"23034\"\n", "rollbar_uuid": "4921c5bc-1ef6-49f9-b8a2-2d693b3f833d", "traceback": "Traceback (most recent call last):\n  File \"/Users/noah/Otis/backend/service/lib/utils/wrappers.py\", line 17, in wrap\n    return_value = func(*args, **kwargs)\n  File \"./impl/__init__.py\", line 39, in GetGeneralMerchant\n    m = Merchant()\n  File \"<string>\", line 4, in __init__\n  File \"/Users/noah/Otis/backend/service/merchant/merchant-service-venv/lib/python3.7/site-packages/sqlalchemy/orm/state.py\", line 433, in _initialize_instance\n    manager.dispatch.init_failure(self, args, kwargs)\n  File \"/Users/noah/Otis/backend/service/merchant/merchant-service-venv/lib/python3.7/site-packages/sqlalchemy/util/langhelpers.py\", line 69, in __exit__\n    exc_value, with_traceback=exc_tb,\n  File \"/Users/noah/Otis/backend/service/merchant/merchant-service-venv/lib/python3.7/site-packages/sqlalchemy/util/compat.py\", line 178, in raise_\n    raise exception\n  File \"/Users/noah/Otis/backend/service/merchant/merchant-service-venv/lib/python3.7/site-packages/sqlalchemy/orm/state.py\", line 430, in _initialize_instance\n    return manager.original_init(*mixed[1:], **kwargs)\n  File \"/Users/noah/Otis/backend/service/lib/psql/schemas/merchant.py\", line 16, in __init__\n    AddressMixin.__init__(nullable=False)\nTypeError: __init__() missing 1 required positional argument: 'self'\n"}
{"message": "Error in call to GetGeneralMerchant: TypeError(\"__init__() got an unexpected keyword argument 'name'\")", "level": "ERROR", "name": "merchant-service", "time": "2020-06-04T12:49:55.422332", "request": "merchantID: \"23034\"\n", "rollbar_uuid": "015140de-32f4-47a3-be8a-531f632f990a", "traceback": "Traceback (most recent call last):\n  File \"/Users/noah/Otis/backend/service/lib/utils/wrappers.py\", line 17, in wrap\n    return_value = func(*args, **kwargs)\n  File \"./impl/__init__.py\", line 38, in GetGeneralMerchant\n    m = Merchant(name='hjkl')\nTypeError: __init__() got an unexpected keyword argument 'name'\n"}
{"message": "Error in call to GetGeneralMerchant: TypeError(\"__init__() got an unexpected keyword argument 'name'\")", "level": "ERROR", "name": "merchant-service", "time": "2020-06-04T13:28:43.252406", "request": "merchantID: \"23034\"\n", "rollbar_uuid": "61c0f52a-9099-4596-bf1c-ebef653dc3a3", "traceback": "Traceback (most recent call last):\n  File \"/Users/noah/Otis/backend/service/lib/utils/wrappers.py\", line 17, in wrap\n    return_value = func(*args, **kwargs)\n  File \"./impl/__init__.py\", line 38, in GetGeneralMerchant\n    m = Merchant(name='hjkl')\nTypeError: __init__() got an unexpected keyword argument 'name'\n"}
{"message": "Error in call to GetGeneralMerchant: AttributeError(\"'Merchant' object has no attribute 'info'\")", "level": "ERROR", "name": "merchant-service", "time": "2020-06-04T13:35:24.769360", "request": "merchantID: \"23034\"\n", "rollbar_uuid": "749f5f7a-fea0-4126-a8e6-4c6b988f2c79", "traceback": "Traceback (most recent call last):\n  File \"/Users/noah/Otis/backend/service/lib/utils/wrappers.py\", line 17, in wrap\n    return_value = func(*args, **kwargs)\n  File \"./impl/__init__.py\", line 39, in GetGeneralMerchant\n    print(m.info)\nAttributeError: 'Merchant' object has no attribute 'info'\n"}
{"message": "Error in call to GetGeneralMerchant: AttributeError(\"'Merchant' object has no attribute 'columns'\")", "level": "ERROR", "name": "merchant-service", "time": "2020-06-04T13:36:08.797191", "request": "merchantID: \"23034\"\n", "rollbar_uuid": "d2cd1207-cde7-4f1d-87d2-49b6a925698b", "traceback": "Traceback (most recent call last):\n  File \"/Users/noah/Otis/backend/service/lib/utils/wrappers.py\", line 17, in wrap\n    return_value = func(*args, **kwargs)\n  File \"./impl/__init__.py\", line 39, in GetGeneralMerchant\n    print(m.columns)\nAttributeError: 'Merchant' object has no attribute 'columns'\n"}
{"message": "Error in call to GetGeneralMerchant: AttributeError(\"type object 'Base' has no attribute 'columns'\")", "level": "ERROR", "name": "merchant-service", "time": "2020-06-04T13:37:14.364661", "request": "merchantID: \"23034\"\n", "rollbar_uuid": "aa8aff09-e168-4ca7-9085-ff01160c7bf2", "traceback": "Traceback (most recent call last):\n  File \"/Users/noah/Otis/backend/service/lib/utils/wrappers.py\", line 17, in wrap\n    return_value = func(*args, **kwargs)\n  File \"./impl/__init__.py\", line 39, in GetGeneralMerchant\n    print(MerchantBase.columns)\nAttributeError: type object 'Base' has no attribute 'columns'\n"}
{"message": "Error in call to GetGeneralMerchant: AttributeError(\"type object 'Base' has no attribute '__table__'\")", "level": "ERROR", "name": "merchant-service", "time": "2020-06-04T13:54:07.893392", "request": "merchantID: \"23034\"\n", "rollbar_uuid": "359a9405-bb0f-4c67-8454-f5ec3a095eac", "traceback": "Traceback (most recent call last):\n  File \"/Users/noah/Otis/backend/service/lib/utils/wrappers.py\", line 17, in wrap\n    return_value = func(*args, **kwargs)\n  File \"./impl/__init__.py\", line 39, in GetGeneralMerchant\n    print(MerchantBase.__table__)\nAttributeError: type object 'Base' has no attribute '__table__'\n"}
{"message": "Error in call to GetGeneralMerchant: UnboundExecutionError('MetaData object is not bound to an Engine or Connection.  Execution can not proceed without a database to execute against.')", "level": "ERROR", "name": "merchant-service", "time": "2020-06-04T14:06:39.272132", "request": "merchantID: \"23034\"\n", "rollbar_uuid": "698fd7ac-f251-4fb6-ae67-c693c3de0fe4", "traceback": "Traceback (most recent call last):\n  File \"/Users/noah/Otis/backend/service/lib/utils/wrappers.py\", line 17, in wrap\n    return_value = func(*args, **kwargs)\n  File \"./impl/__init__.py\", line 39, in GetGeneralMerchant\n    print(Merchant.metadata.create_all())\n  File \"/Users/noah/Otis/backend/service/merchant/merchant-service-venv/lib/python3.7/site-packages/sqlalchemy/sql/schema.py\", line 4463, in create_all\n    bind = _bind_or_error(self)\n  File \"/Users/noah/Otis/backend/service/merchant/merchant-service-venv/lib/python3.7/site-packages/sqlalchemy/sql/base.py\", line 676, in _bind_or_error\n    raise exc.UnboundExecutionError(msg)\nsqlalchemy.exc.UnboundExecutionError: MetaData object is not bound to an Engine or Connection.  Execution can not proceed without a database to execute against.\n"}
{"message": "Error in call to GetGeneralMerchant: CompileError(\"(in table 'merchants', column 'created_at'): Can't generate DDL for NullType(); did you forget to specify a type on this Column?\")", "level": "ERROR", "name": "merchant-service", "time": "2020-06-04T14:13:43.047985", "request": "merchantID: \"23034\"\n", "rollbar_uuid": "2adb3211-5863-42f7-88fa-d41bcdc4db32", "traceback": "Traceback (most recent call last):\n  File \"/Users/noah/Otis/backend/service/merchant/merchant-service-venv/lib/python3.7/site-packages/sqlalchemy/sql/compiler.py\", line 2897, in visit_create_table\n    create_column, first_pk=column.primary_key and not first_pk\n  File \"/Users/noah/Otis/backend/service/merchant/merchant-service-venv/lib/python3.7/site-packages/sqlalchemy/sql/compiler.py\", line 350, in process\n    return obj._compiler_dispatch(self, **kwargs)\n  File \"/Users/noah/Otis/backend/service/merchant/merchant-service-venv/lib/python3.7/site-packages/sqlalchemy/sql/visitors.py\", line 95, in _compiler_dispatch\n    return meth(self, **kw)\n  File \"/Users/noah/Otis/backend/service/merchant/merchant-service-venv/lib/python3.7/site-packages/sqlalchemy/sql/compiler.py\", line 2930, in visit_create_column\n    text = self.get_column_specification(column, first_pk=first_pk)\n  File \"/Users/noah/Otis/backend/service/merchant/merchant-service-venv/lib/python3.7/site-packages/sqlalchemy/dialects/postgresql/base.py\", line 1937, in get_column_specification\n    identifier_preparer=self.preparer,\n  File \"/Users/noah/Otis/backend/service/merchant/merchant-service-venv/lib/python3.7/site-packages/sqlalchemy/sql/compiler.py\", line 400, in process\n    return type_._compiler_dispatch(self, **kw)\n  File \"/Users/noah/Otis/backend/service/merchant/merchant-service-venv/lib/python3.7/site-packages/sqlalchemy/sql/visitors.py\", line 95, in _compiler_dispatch\n    return meth(self, **kw)\n  File \"/Users/noah/Otis/backend/service/merchant/merchant-service-venv/lib/python3.7/site-packages/sqlalchemy/sql/compiler.py\", line 3436, in visit_null\n    \"type on this Column?\" % type_\nsqlalchemy.exc.CompileError: Can't generate DDL for NullType(); did you forget to specify a type on this Column?\n\nThe above exception was the direct cause of the following exception:\n\nTraceback (most recent call last):\n  File \"/Users/noah/Otis/backend/service/lib/utils/wrappers.py\", line 17, in wrap\n    return_value = func(*args, **kwargs)\n  File \"./impl/__init__.py\", line 42, in GetGeneralMerchant\n    print(CreateTable(Merchant.__table__).compile(dialect=postgresql.dialect()))\n  File \"<string>\", line 1, in <lambda>\n  File \"/Users/noah/Otis/backend/service/merchant/merchant-service-venv/lib/python3.7/site-packages/sqlalchemy/sql/elements.py\", line 476, in compile\n    return self._compiler(dialect, bind=bind, **kw)\n  File \"/Users/noah/Otis/backend/service/merchant/merchant-service-venv/lib/python3.7/site-packages/sqlalchemy/sql/ddl.py\", line 29, in _compiler\n    return dialect.ddl_compiler(dialect, self, **kw)\n  File \"/Users/noah/Otis/backend/service/merchant/merchant-service-venv/lib/python3.7/site-packages/sqlalchemy/sql/compiler.py\", line 319, in __init__\n    self.string = self.process(self.statement, **compile_kwargs)\n  File \"/Users/noah/Otis/backend/service/merchant/merchant-service-venv/lib/python3.7/site-packages/sqlalchemy/sql/compiler.py\", line 350, in process\n    return obj._compiler_dispatch(self, **kwargs)\n  File \"/Users/noah/Otis/backend/service/merchant/merchant-service-venv/lib/python3.7/site-packages/sqlalchemy/sql/visitors.py\", line 95, in _compiler_dispatch\n    return meth(self, **kw)\n  File \"/Users/noah/Otis/backend/service/merchant/merchant-service-venv/lib/python3.7/site-packages/sqlalchemy/sql/compiler.py\", line 2911, in visit_create_table\n    from_=ce,\n  File \"/Users/noah/Otis/backend/service/merchant/merchant-service-venv/lib/python3.7/site-packages/sqlalchemy/util/compat.py\", line 178, in raise_\n    raise exception\nsqlalchemy.exc.CompileError: (in table 'merchants', column 'created_at'): Can't generate DDL for NullType(); did you forget to specify a type on this Column?\n"}
{"message": "Error in call to GetGeneralMerchant: CompileError(\"(in table 'merchants', column 'created_at'): Can't generate DDL for NullType(); did you forget to specify a type on this Column?\")", "level": "ERROR", "name": "merchant-service", "time": "2020-06-04T14:15:26.078313", "request": "merchantID: \"23034\"\n", "rollbar_uuid": "6d611adf-423a-48da-bd03-2a45894db2ef", "traceback": "Traceback (most recent call last):\n  File \"/Users/noah/Otis/backend/service/merchant/merchant-service-venv/lib/python3.7/site-packages/sqlalchemy/sql/compiler.py\", line 2897, in visit_create_table\n    create_column, first_pk=column.primary_key and not first_pk\n  File \"/Users/noah/Otis/backend/service/merchant/merchant-service-venv/lib/python3.7/site-packages/sqlalchemy/sql/compiler.py\", line 350, in process\n    return obj._compiler_dispatch(self, **kwargs)\n  File \"/Users/noah/Otis/backend/service/merchant/merchant-service-venv/lib/python3.7/site-packages/sqlalchemy/sql/visitors.py\", line 95, in _compiler_dispatch\n    return meth(self, **kw)\n  File \"/Users/noah/Otis/backend/service/merchant/merchant-service-venv/lib/python3.7/site-packages/sqlalchemy/sql/compiler.py\", line 2930, in visit_create_column\n    text = self.get_column_specification(column, first_pk=first_pk)\n  File \"/Users/noah/Otis/backend/service/merchant/merchant-service-venv/lib/python3.7/site-packages/sqlalchemy/dialects/postgresql/base.py\", line 1937, in get_column_specification\n    identifier_preparer=self.preparer,\n  File \"/Users/noah/Otis/backend/service/merchant/merchant-service-venv/lib/python3.7/site-packages/sqlalchemy/sql/compiler.py\", line 400, in process\n    return type_._compiler_dispatch(self, **kw)\n  File \"/Users/noah/Otis/backend/service/merchant/merchant-service-venv/lib/python3.7/site-packages/sqlalchemy/sql/visitors.py\", line 95, in _compiler_dispatch\n    return meth(self, **kw)\n  File \"/Users/noah/Otis/backend/service/merchant/merchant-service-venv/lib/python3.7/site-packages/sqlalchemy/sql/compiler.py\", line 3436, in visit_null\n    \"type on this Column?\" % type_\nsqlalchemy.exc.CompileError: Can't generate DDL for NullType(); did you forget to specify a type on this Column?\n\nThe above exception was the direct cause of the following exception:\n\nTraceback (most recent call last):\n  File \"/Users/noah/Otis/backend/service/lib/utils/wrappers.py\", line 17, in wrap\n    return_value = func(*args, **kwargs)\n  File \"./impl/__init__.py\", line 42, in GetGeneralMerchant\n    print(CreateTable(Merchant.__table__).compile(dialect=postgresql.dialect()))\n  File \"<string>\", line 1, in <lambda>\n  File \"/Users/noah/Otis/backend/service/merchant/merchant-service-venv/lib/python3.7/site-packages/sqlalchemy/sql/elements.py\", line 476, in compile\n    return self._compiler(dialect, bind=bind, **kw)\n  File \"/Users/noah/Otis/backend/service/merchant/merchant-service-venv/lib/python3.7/site-packages/sqlalchemy/sql/ddl.py\", line 29, in _compiler\n    return dialect.ddl_compiler(dialect, self, **kw)\n  File \"/Users/noah/Otis/backend/service/merchant/merchant-service-venv/lib/python3.7/site-packages/sqlalchemy/sql/compiler.py\", line 319, in __init__\n    self.string = self.process(self.statement, **compile_kwargs)\n  File \"/Users/noah/Otis/backend/service/merchant/merchant-service-venv/lib/python3.7/site-packages/sqlalchemy/sql/compiler.py\", line 350, in process\n    return obj._compiler_dispatch(self, **kwargs)\n  File \"/Users/noah/Otis/backend/service/merchant/merchant-service-venv/lib/python3.7/site-packages/sqlalchemy/sql/visitors.py\", line 95, in _compiler_dispatch\n    return meth(self, **kw)\n  File \"/Users/noah/Otis/backend/service/merchant/merchant-service-venv/lib/python3.7/site-packages/sqlalchemy/sql/compiler.py\", line 2911, in visit_create_table\n    from_=ce,\n  File \"/Users/noah/Otis/backend/service/merchant/merchant-service-venv/lib/python3.7/site-packages/sqlalchemy/util/compat.py\", line 178, in raise_\n    raise exception\nsqlalchemy.exc.CompileError: (in table 'merchants', column 'created_at'): Can't generate DDL for NullType(); did you forget to specify a type on this Column?\n"}
{"message": "Error in call to GetGeneralMerchant: CompileError(\"(in table 'merchants', column 'created_at'): Can't generate DDL for NullType(); did you forget to specify a type on this Column?\")", "level": "ERROR", "name": "merchant-service", "time": "2020-06-04T14:15:49.234768", "request": "merchantID: \"23034\"\n", "rollbar_uuid": "869db43e-07c3-40e4-8004-a94bcffee7aa", "traceback": "Traceback (most recent call last):\n  File \"/Users/noah/Otis/backend/service/merchant/merchant-service-venv/lib/python3.7/site-packages/sqlalchemy/sql/compiler.py\", line 2897, in visit_create_table\n    create_column, first_pk=column.primary_key and not first_pk\n  File \"/Users/noah/Otis/backend/service/merchant/merchant-service-venv/lib/python3.7/site-packages/sqlalchemy/sql/compiler.py\", line 350, in process\n    return obj._compiler_dispatch(self, **kwargs)\n  File \"/Users/noah/Otis/backend/service/merchant/merchant-service-venv/lib/python3.7/site-packages/sqlalchemy/sql/visitors.py\", line 95, in _compiler_dispatch\n    return meth(self, **kw)\n  File \"/Users/noah/Otis/backend/service/merchant/merchant-service-venv/lib/python3.7/site-packages/sqlalchemy/sql/compiler.py\", line 2930, in visit_create_column\n    text = self.get_column_specification(column, first_pk=first_pk)\n  File \"/Users/noah/Otis/backend/service/merchant/merchant-service-venv/lib/python3.7/site-packages/sqlalchemy/dialects/postgresql/base.py\", line 1937, in get_column_specification\n    identifier_preparer=self.preparer,\n  File \"/Users/noah/Otis/backend/service/merchant/merchant-service-venv/lib/python3.7/site-packages/sqlalchemy/sql/compiler.py\", line 400, in process\n    return type_._compiler_dispatch(self, **kw)\n  File \"/Users/noah/Otis/backend/service/merchant/merchant-service-venv/lib/python3.7/site-packages/sqlalchemy/sql/visitors.py\", line 95, in _compiler_dispatch\n    return meth(self, **kw)\n  File \"/Users/noah/Otis/backend/service/merchant/merchant-service-venv/lib/python3.7/site-packages/sqlalchemy/sql/compiler.py\", line 3436, in visit_null\n    \"type on this Column?\" % type_\nsqlalchemy.exc.CompileError: Can't generate DDL for NullType(); did you forget to specify a type on this Column?\n\nThe above exception was the direct cause of the following exception:\n\nTraceback (most recent call last):\n  File \"/Users/noah/Otis/backend/service/lib/utils/wrappers.py\", line 17, in wrap\n    return_value = func(*args, **kwargs)\n  File \"./impl/__init__.py\", line 42, in GetGeneralMerchant\n    print(CreateTable(Merchant.__table__).compile(dialect=postgresql.dialect()))\n  File \"<string>\", line 1, in <lambda>\n  File \"/Users/noah/Otis/backend/service/merchant/merchant-service-venv/lib/python3.7/site-packages/sqlalchemy/sql/elements.py\", line 476, in compile\n    return self._compiler(dialect, bind=bind, **kw)\n  File \"/Users/noah/Otis/backend/service/merchant/merchant-service-venv/lib/python3.7/site-packages/sqlalchemy/sql/ddl.py\", line 29, in _compiler\n    return dialect.ddl_compiler(dialect, self, **kw)\n  File \"/Users/noah/Otis/backend/service/merchant/merchant-service-venv/lib/python3.7/site-packages/sqlalchemy/sql/compiler.py\", line 319, in __init__\n    self.string = self.process(self.statement, **compile_kwargs)\n  File \"/Users/noah/Otis/backend/service/merchant/merchant-service-venv/lib/python3.7/site-packages/sqlalchemy/sql/compiler.py\", line 350, in process\n    return obj._compiler_dispatch(self, **kwargs)\n  File \"/Users/noah/Otis/backend/service/merchant/merchant-service-venv/lib/python3.7/site-packages/sqlalchemy/sql/visitors.py\", line 95, in _compiler_dispatch\n    return meth(self, **kw)\n  File \"/Users/noah/Otis/backend/service/merchant/merchant-service-venv/lib/python3.7/site-packages/sqlalchemy/sql/compiler.py\", line 2911, in visit_create_table\n    from_=ce,\n  File \"/Users/noah/Otis/backend/service/merchant/merchant-service-venv/lib/python3.7/site-packages/sqlalchemy/util/compat.py\", line 178, in raise_\n    raise exception\nsqlalchemy.exc.CompileError: (in table 'merchants', column 'created_at'): Can't generate DDL for NullType(); did you forget to specify a type on this Column?\n"}
{"message": "Error in call to GetGeneralMerchant: TypeError(\"__init__() got an unexpected keyword argument 'dialect'\")", "level": "ERROR", "name": "merchant-service", "time": "2020-06-04T14:21:39.464046", "request": "merchantID: \"23034\"\n", "rollbar_uuid": "f34e4938-f46b-4b23-ae18-3c06cd80e7e8", "traceback": "Traceback (most recent call last):\n  File \"/Users/noah/Otis/backend/service/lib/utils/wrappers.py\", line 17, in wrap\n    return_value = func(*args, **kwargs)\n  File \"./impl/__init__.py\", line 42, in GetGeneralMerchant\n    print(CreateTable(Merchant.__table__, dialect=postgresql.dialect()))\nTypeError: __init__() got an unexpected keyword argument 'dialect'\n"}
{"message": "Error in call to GetGeneralMerchant: TypeError(\"compile() got multiple values for argument 'default'\")", "level": "ERROR", "name": "merchant-service", "time": "2020-06-04T15:21:26.625142", "request": "merchantID: \"23034\"\n", "rollbar_uuid": "f0aa8465-f1bc-4e2d-bc14-8e1ca5a75549", "traceback": "Traceback (most recent call last):\n  File \"/Users/noah/Otis/backend/service/lib/utils/wrappers.py\", line 17, in wrap\n    return_value = func(*args, **kwargs)\n  File \"./impl/__init__.py\", line 40, in GetGeneralMerchant\n    print(CreateTable(Merchant.__table__).compile(dialect=postgresql.dialect(), default=None) + \";\")\n  File \"<string>\", line 1, in <lambda>\nTypeError: compile() got multiple values for argument 'default'\n"}
{"message": "Error in call to GetGeneralMerchant: TypeError(\"compile() got multiple values for argument 'default'\")", "level": "ERROR", "name": "merchant-service", "time": "2020-06-04T15:23:54.029361", "request": "merchantID: \"23034\"\n", "rollbar_uuid": "b6c350b6-3bc0-464d-825d-e63f5a9a967a", "traceback": "Traceback (most recent call last):\n  File \"/Users/noah/Otis/backend/service/lib/utils/wrappers.py\", line 17, in wrap\n    return_value = func(*args, **kwargs)\n  File \"./impl/__init__.py\", line 40, in GetGeneralMerchant\n    print(CreateTable(Merchant.__table__).compile(default=postgresql.dialect()) + \";\")\n  File \"<string>\", line 1, in <lambda>\nTypeError: compile() got multiple values for argument 'default'\n"}
{"message": "Error in call to GetGeneralMerchant: TypeError(\"unsupported operand type(s) for +: 'PGDDLCompiler' and 'str'\")", "level": "ERROR", "name": "merchant-service", "time": "2020-06-04T15:24:29.534897", "request": "merchantID: \"23034\"\n", "rollbar_uuid": "6f768f9f-8ba5-45f8-9665-21439961a700", "traceback": "Traceback (most recent call last):\n  File \"/Users/noah/Otis/backend/service/lib/utils/wrappers.py\", line 17, in wrap\n    return_value = func(*args, **kwargs)\n  File \"./impl/__init__.py\", line 40, in GetGeneralMerchant\n    print(CreateTable(Merchant.__table__).compile(dialect=postgresql.dialect()) + \";\")\nTypeError: unsupported operand type(s) for +: 'PGDDLCompiler' and 'str'\n"}
{"message": "Error in call to GetGeneralMerchant: ArgumentError(\"Could not parse rfc1738 URL from string 'postgresql%3A%2F%2Fotis%3AcR4K%264NX2AGz%40otis-db-cluster-1.cluster-c6af70dxq6zw.eu-west-2.rds.amazonaws.com%3A5432%2Fotisdb'\")", "level": "ERROR", "name": "merchant-service", "time": "2020-06-04T15:51:56.383668", "request": "merchantID: \"23034\"\n", "rollbar_uuid": "3ef004a9-1451-44a7-8d2d-0484a390b8fb", "traceback": "Traceback (most recent call last):\n  File \"/Users/noah/Otis/backend/service/lib/utils/wrappers.py\", line 17, in wrap\n    return_value = func(*args, **kwargs)\n  File \"./impl/__init__.py\", line 40, in GetGeneralMerchant\n    engine = get_engine()\n  File \"/Users/noah/Otis/backend/service/lib/psql/connection.py\", line 33, in get_engine\n    return sqlalchemy.create_engine(db_conn_string, **kwargs)\n  File \"/Users/noah/Otis/backend/service/merchant/merchant-service-venv/lib/python3.7/site-packages/sqlalchemy/engine/__init__.py\", line 488, in create_engine\n    return strategy.create(*args, **kwargs)\n  File \"/Users/noah/Otis/backend/service/merchant/merchant-service-venv/lib/python3.7/site-packages/sqlalchemy/engine/strategies.py\", line 54, in create\n    u = url.make_url(name_or_url)\n  File \"/Users/noah/Otis/backend/service/merchant/merchant-service-venv/lib/python3.7/site-packages/sqlalchemy/engine/url.py\", line 229, in make_url\n    return _parse_rfc1738_args(name_or_url)\n  File \"/Users/noah/Otis/backend/service/merchant/merchant-service-venv/lib/python3.7/site-packages/sqlalchemy/engine/url.py\", line 291, in _parse_rfc1738_args\n    \"Could not parse rfc1738 URL from string '%s'\" % name\nsqlalchemy.exc.ArgumentError: Could not parse rfc1738 URL from string 'postgresql%3A%2F%2Fotis%3AcR4K%264NX2AGz%40otis-db-cluster-1.cluster-c6af70dxq6zw.eu-west-2.rds.amazonaws.com%3A5432%2Fotisdb'\n"}
{"message": "Error in call to GetGeneralMerchant: ArgumentError(\"Could not parse rfc1738 URL from string 'postgresql%3A%2F%2Fotis%3AcR4K%264NX2AGz%40otis-db-cluster-1.cluster-c6af70dxq6zw.eu-west-2.rds.amazonaws.com%3A5432%2Fotisdb'\")", "level": "ERROR", "name": "merchant-service", "time": "2020-06-04T15:53:20.260074", "request": "merchantID: \"23034\"\n", "rollbar_uuid": "130bb452-dde0-488d-b067-3415e6d9c8a6", "traceback": "Traceback (most recent call last):\n  File \"/Users/noah/Otis/backend/service/lib/utils/wrappers.py\", line 17, in wrap\n    return_value = func(*args, **kwargs)\n  File \"./impl/__init__.py\", line 40, in GetGeneralMerchant\n    engine = get_engine(strategy='mock', executor=dump_psql)\n  File \"/Users/noah/Otis/backend/service/lib/psql/connection.py\", line 33, in get_engine\n    return sqlalchemy.create_engine(db_conn_string, **kwargs)\n  File \"/Users/noah/Otis/backend/service/merchant/merchant-service-venv/lib/python3.7/site-packages/sqlalchemy/engine/__init__.py\", line 488, in create_engine\n    return strategy.create(*args, **kwargs)\n  File \"/Users/noah/Otis/backend/service/merchant/merchant-service-venv/lib/python3.7/site-packages/sqlalchemy/engine/strategies.py\", line 251, in create\n    u = url.make_url(name_or_url)\n  File \"/Users/noah/Otis/backend/service/merchant/merchant-service-venv/lib/python3.7/site-packages/sqlalchemy/engine/url.py\", line 229, in make_url\n    return _parse_rfc1738_args(name_or_url)\n  File \"/Users/noah/Otis/backend/service/merchant/merchant-service-venv/lib/python3.7/site-packages/sqlalchemy/engine/url.py\", line 291, in _parse_rfc1738_args\n    \"Could not parse rfc1738 URL from string '%s'\" % name\nsqlalchemy.exc.ArgumentError: Could not parse rfc1738 URL from string 'postgresql%3A%2F%2Fotis%3AcR4K%264NX2AGz%40otis-db-cluster-1.cluster-c6af70dxq6zw.eu-west-2.rds.amazonaws.com%3A5432%2Fotisdb'\n"}
{"message": "Error in call to GetGeneralMerchant: TypeError(\"create() missing 1 required positional argument: 'name_or_url'\")", "level": "ERROR", "name": "merchant-service", "time": "2020-06-04T15:54:05.264525", "request": "merchantID: \"23034\"\n", "rollbar_uuid": "41f17a1c-0123-45ec-8a1d-e9db9530f9c3", "traceback": "Traceback (most recent call last):\n  File \"/Users/noah/Otis/backend/service/lib/utils/wrappers.py\", line 17, in wrap\n    return_value = func(*args, **kwargs)\n  File \"./impl/__init__.py\", line 40, in GetGeneralMerchant\n    engine = get_engine(strategy='mock', executor=dump_psql)\n  File \"/Users/noah/Otis/backend/service/lib/psql/connection.py\", line 33, in get_engine\n    return sqlalchemy.create_engine(**kwargs)\n  File \"/Users/noah/Otis/backend/service/merchant/merchant-service-venv/lib/python3.7/site-packages/sqlalchemy/engine/__init__.py\", line 488, in create_engine\n    return strategy.create(*args, **kwargs)\nTypeError: create() missing 1 required positional argument: 'name_or_url'\n"}
{"message": "Error in call to GetGeneralMerchant: AttributeError(\"'Table' object has no attribute 'create_all'\")", "level": "ERROR", "name": "merchant-service", "time": "2020-06-04T15:54:29.308077", "request": "merchantID: \"23034\"\n", "rollbar_uuid": "64206aa7-1a25-48ab-9c97-2a1bbf1d79eb", "traceback": "Traceback (most recent call last):\n  File \"/Users/noah/Otis/backend/service/lib/utils/wrappers.py\", line 17, in wrap\n    return_value = func(*args, **kwargs)\n  File \"./impl/__init__.py\", line 41, in GetGeneralMerchant\n    print(Merchant.__table__.create_all(engine, checkfirst=False))\nAttributeError: 'Table' object has no attribute 'create_all'\n"}
{"message": "Error in call to GetGeneralMerchant: TypeError(\"'module' object is not callable\")", "level": "ERROR", "name": "merchant-service", "time": "2020-06-04T15:55:11.708622", "request": "merchantID: \"23034\"\n", "rollbar_uuid": "09063a56-7e70-4fbe-95ce-a5b22261956a", "traceback": "Traceback (most recent call last):\n  File \"/Users/noah/Otis/backend/service/lib/utils/wrappers.py\", line 17, in wrap\n    return_value = func(*args, **kwargs)\n  File \"./impl/__init__.py\", line 41, in GetGeneralMerchant\n    print(Merchant.metadata.create_all(engine, checkfirst=False))\n  File \"/Users/noah/Otis/backend/service/merchant/merchant-service-venv/lib/python3.7/site-packages/sqlalchemy/sql/schema.py\", line 4465, in create_all\n    ddl.SchemaGenerator, self, checkfirst=checkfirst, tables=tables\n  File \"/Users/noah/Otis/backend/service/merchant/merchant-service-venv/lib/python3.7/site-packages/sqlalchemy/engine/strategies.py\", line 312, in _run_visitor\n    element\n  File \"/Users/noah/Otis/backend/service/merchant/merchant-service-venv/lib/python3.7/site-packages/sqlalchemy/sql/visitors.py\", line 144, in traverse_single\n    return meth(obj, **kw)\n  File \"/Users/noah/Otis/backend/service/merchant/merchant-service-venv/lib/python3.7/site-packages/sqlalchemy/sql/ddl.py\", line 787, in visit_metadata\n    _is_metadata_operation=True,\n  File \"/Users/noah/Otis/backend/service/merchant/merchant-service-venv/lib/python3.7/site-packages/sqlalchemy/sql/visitors.py\", line 144, in traverse_single\n    return meth(obj, **kw)\n  File \"/Users/noah/Otis/backend/service/merchant/merchant-service-venv/lib/python3.7/site-packages/sqlalchemy/sql/ddl.py\", line 832, in visit_table\n    include_foreign_key_constraints,  # noqa\n  File \"/Users/noah/Otis/backend/service/lib/psql/connection.py\", line 27, in dump_psql\n    print(sql.compile(dialect=sqlalchemy.dialects.postgresql()))\nTypeError: 'module' object is not callable\n"}
{"message": "Error in call to GetGeneralMerchant: TypeError(\"'module' object is not callable\")", "level": "ERROR", "name": "merchant-service", "time": "2020-06-04T15:56:28.303702", "request": "merchantID: \"23034\"\n", "rollbar_uuid": "5fc7bd80-7e1a-4ade-8af7-3a46ac7267ed", "traceback": "Traceback (most recent call last):\n  File \"/Users/noah/Otis/backend/service/lib/utils/wrappers.py\", line 17, in wrap\n    return_value = func(*args, **kwargs)\n  File \"./impl/__init__.py\", line 41, in GetGeneralMerchant\n    print(Merchant.metadata.create_all(engine, checkfirst=False))\n  File \"/Users/noah/Otis/backend/service/merchant/merchant-service-venv/lib/python3.7/site-packages/sqlalchemy/sql/schema.py\", line 4465, in create_all\n    ddl.SchemaGenerator, self, checkfirst=checkfirst, tables=tables\n  File \"/Users/noah/Otis/backend/service/merchant/merchant-service-venv/lib/python3.7/site-packages/sqlalchemy/engine/strategies.py\", line 312, in _run_visitor\n    element\n  File \"/Users/noah/Otis/backend/service/merchant/merchant-service-venv/lib/python3.7/site-packages/sqlalchemy/sql/visitors.py\", line 144, in traverse_single\n    return meth(obj, **kw)\n  File \"/Users/noah/Otis/backend/service/merchant/merchant-service-venv/lib/python3.7/site-packages/sqlalchemy/sql/ddl.py\", line 787, in visit_metadata\n    _is_metadata_operation=True,\n  File \"/Users/noah/Otis/backend/service/merchant/merchant-service-venv/lib/python3.7/site-packages/sqlalchemy/sql/visitors.py\", line 144, in traverse_single\n    return meth(obj, **kw)\n  File \"/Users/noah/Otis/backend/service/merchant/merchant-service-venv/lib/python3.7/site-packages/sqlalchemy/sql/ddl.py\", line 832, in visit_table\n    include_foreign_key_constraints,  # noqa\n  File \"/Users/noah/Otis/backend/service/lib/psql/connection.py\", line 28, in dump_psql\n    print(sql.compile(dialect=postgresql()))\nTypeError: 'module' object is not callable\n"}
{"message": "Error in call to GetGeneralMerchant: TypeError(\"'module' object is not callable\")", "level": "ERROR", "name": "merchant-service", "time": "2020-06-04T15:56:56.115433", "request": "merchantID: \"23034\"\n", "rollbar_uuid": "b90a6f08-2631-4816-8cb7-dc0f512535b3", "traceback": "Traceback (most recent call last):\n  File \"/Users/noah/Otis/backend/service/lib/utils/wrappers.py\", line 17, in wrap\n    return_value = func(*args, **kwargs)\n  File \"./impl/__init__.py\", line 41, in GetGeneralMerchant\n    print(Merchant.metadata.create_all(engine, checkfirst=False))\n  File \"/Users/noah/Otis/backend/service/merchant/merchant-service-venv/lib/python3.7/site-packages/sqlalchemy/sql/schema.py\", line 4465, in create_all\n    ddl.SchemaGenerator, self, checkfirst=checkfirst, tables=tables\n  File \"/Users/noah/Otis/backend/service/merchant/merchant-service-venv/lib/python3.7/site-packages/sqlalchemy/engine/strategies.py\", line 312, in _run_visitor\n    element\n  File \"/Users/noah/Otis/backend/service/merchant/merchant-service-venv/lib/python3.7/site-packages/sqlalchemy/sql/visitors.py\", line 144, in traverse_single\n    return meth(obj, **kw)\n  File \"/Users/noah/Otis/backend/service/merchant/merchant-service-venv/lib/python3.7/site-packages/sqlalchemy/sql/ddl.py\", line 787, in visit_metadata\n    _is_metadata_operation=True,\n  File \"/Users/noah/Otis/backend/service/merchant/merchant-service-venv/lib/python3.7/site-packages/sqlalchemy/sql/visitors.py\", line 144, in traverse_single\n    return meth(obj, **kw)\n  File \"/Users/noah/Otis/backend/service/merchant/merchant-service-venv/lib/python3.7/site-packages/sqlalchemy/sql/ddl.py\", line 832, in visit_table\n    include_foreign_key_constraints,  # noqa\n  File \"/Users/noah/Otis/backend/service/lib/psql/connection.py\", line 28, in dump_psql\n    print(sql.compile(dialect=dialects.postgresql()))\nTypeError: 'module' object is not callable\n"}
{"message": "Error in call to GetGeneralMerchant: TypeError(\"'str' object is not callable\")", "level": "ERROR", "name": "merchant-service", "time": "2020-06-04T16:29:40.624702", "request": "merchantID: \"23034\"\n", "rollbar_uuid": "b296de6b-8a69-4fce-9726-b75932d98af2", "traceback": "Traceback (most recent call last):\n  File \"/Users/noah/Otis/backend/service/lib/utils/wrappers.py\", line 17, in wrap\n    return_value = func(*args, **kwargs)\n  File \"./impl/__init__.py\", line 41, in GetGeneralMerchant\n    print(Merchant.metadata.create_all(self.db_engine, checkfirst=False))\n  File \"/Users/noah/Otis/backend/service/merchant/merchant-service-venv/lib/python3.7/site-packages/sqlalchemy/sql/schema.py\", line 4465, in create_all\n    ddl.SchemaGenerator, self, checkfirst=checkfirst, tables=tables\n  File \"/Users/noah/Otis/backend/service/merchant/merchant-service-venv/lib/python3.7/site-packages/sqlalchemy/engine/strategies.py\", line 312, in _run_visitor\n    element\n  File \"/Users/noah/Otis/backend/service/merchant/merchant-service-venv/lib/python3.7/site-packages/sqlalchemy/sql/visitors.py\", line 144, in traverse_single\n    return meth(obj, **kw)\n  File \"/Users/noah/Otis/backend/service/merchant/merchant-service-venv/lib/python3.7/site-packages/sqlalchemy/sql/ddl.py\", line 787, in visit_metadata\n    _is_metadata_operation=True,\n  File \"/Users/noah/Otis/backend/service/merchant/merchant-service-venv/lib/python3.7/site-packages/sqlalchemy/sql/visitors.py\", line 144, in traverse_single\n    return meth(obj, **kw)\n  File \"/Users/noah/Otis/backend/service/merchant/merchant-service-venv/lib/python3.7/site-packages/sqlalchemy/sql/ddl.py\", line 832, in visit_table\n    include_foreign_key_constraints,  # noqa\nTypeError: 'str' object is not callable\n"}
{"message": "Error in call to GetGeneralMerchant: TypeError(\"'str' object is not callable\")", "level": "ERROR", "name": "merchant-service", "time": "2020-06-04T16:32:10.665940", "request": "merchantID: \"23034\"\n", "rollbar_uuid": "712d7b68-fa65-46c3-88bb-8d03ba712496", "traceback": "Traceback (most recent call last):\n  File \"/Users/noah/Otis/backend/service/lib/utils/wrappers.py\", line 17, in wrap\n    return_value = func(*args, **kwargs)\n  File \"./impl/__init__.py\", line 41, in GetGeneralMerchant\n    print(Merchant.metadata.create_all(self.db_engine, checkfirst=False))\n  File \"/Users/noah/Otis/backend/service/merchant/merchant-service-venv/lib/python3.7/site-packages/sqlalchemy/sql/schema.py\", line 4465, in create_all\n    ddl.SchemaGenerator, self, checkfirst=checkfirst, tables=tables\n  File \"/Users/noah/Otis/backend/service/merchant/merchant-service-venv/lib/python3.7/site-packages/sqlalchemy/engine/strategies.py\", line 312, in _run_visitor\n    element\n  File \"/Users/noah/Otis/backend/service/merchant/merchant-service-venv/lib/python3.7/site-packages/sqlalchemy/sql/visitors.py\", line 144, in traverse_single\n    return meth(obj, **kw)\n  File \"/Users/noah/Otis/backend/service/merchant/merchant-service-venv/lib/python3.7/site-packages/sqlalchemy/sql/ddl.py\", line 787, in visit_metadata\n    _is_metadata_operation=True,\n  File \"/Users/noah/Otis/backend/service/merchant/merchant-service-venv/lib/python3.7/site-packages/sqlalchemy/sql/visitors.py\", line 144, in traverse_single\n    return meth(obj, **kw)\n  File \"/Users/noah/Otis/backend/service/merchant/merchant-service-venv/lib/python3.7/site-packages/sqlalchemy/sql/ddl.py\", line 832, in visit_table\n    include_foreign_key_constraints,  # noqa\nTypeError: 'str' object is not callable\n"}
{"message": "Error in call to GetGeneralMerchant: OperationalError('(psycopg2.OperationalError) could not translate host name \"otis-db-cluster-1.cluster-c6af70dxq6zw.eu-west-2.rds.amazonaws.com\" to address: nodename nor servname provided, or not known\\n')", "level": "ERROR", "name": "merchant-service", "time": "2020-06-04T17:01:54.302652", "request": "merchantID: \"23034\"\n", "rollbar_uuid": "615c85f6-4a6e-4cae-bdec-97ea46b6e8e3", "traceback": "Traceback (most recent call last):\n  File \"/Users/noah/Otis/backend/service/merchant/merchant-service-venv/lib/python3.7/site-packages/sqlalchemy/engine/base.py\", line 2345, in _wrap_pool_connect\n    return fn()\n  File \"/Users/noah/Otis/backend/service/merchant/merchant-service-venv/lib/python3.7/site-packages/sqlalchemy/pool/base.py\", line 364, in connect\n    return _ConnectionFairy._checkout(self)\n  File \"/Users/noah/Otis/backend/service/merchant/merchant-service-venv/lib/python3.7/site-packages/sqlalchemy/pool/base.py\", line 778, in _checkout\n    fairy = _ConnectionRecord.checkout(pool)\n  File \"/Users/noah/Otis/backend/service/merchant/merchant-service-venv/lib/python3.7/site-packages/sqlalchemy/pool/base.py\", line 495, in checkout\n    rec = pool._do_get()\n  File \"/Users/noah/Otis/backend/service/merchant/merchant-service-venv/lib/python3.7/site-packages/sqlalchemy/pool/impl.py\", line 140, in _do_get\n    self._dec_overflow()\n  File \"/Users/noah/Otis/backend/service/merchant/merchant-service-venv/lib/python3.7/site-packages/sqlalchemy/util/langhelpers.py\", line 69, in __exit__\n    exc_value, with_traceback=exc_tb,\n  File \"/Users/noah/Otis/backend/service/merchant/merchant-service-venv/lib/python3.7/site-packages/sqlalchemy/util/compat.py\", line 178, in raise_\n    raise exception\n  File \"/Users/noah/Otis/backend/service/merchant/merchant-service-venv/lib/python3.7/site-packages/sqlalchemy/pool/impl.py\", line 137, in _do_get\n    return self._create_connection()\n  File \"/Users/noah/Otis/backend/service/merchant/merchant-service-venv/lib/python3.7/site-packages/sqlalchemy/pool/base.py\", line 309, in _create_connection\n    return _ConnectionRecord(self)\n  File \"/Users/noah/Otis/backend/service/merchant/merchant-service-venv/lib/python3.7/site-packages/sqlalchemy/pool/base.py\", line 440, in __init__\n    self.__connect(first_connect_check=True)\n  File \"/Users/noah/Otis/backend/service/merchant/merchant-service-venv/lib/python3.7/site-packages/sqlalchemy/pool/base.py\", line 661, in __connect\n    pool.logger.debug(\"Error on connect(): %s\", e)\n  File \"/Users/noah/Otis/backend/service/merchant/merchant-service-venv/lib/python3.7/site-packages/sqlalchemy/util/langhelpers.py\", line 69, in __exit__\n    exc_value, with_traceback=exc_tb,\n  File \"/Users/noah/Otis/backend/service/merchant/merchant-service-venv/lib/python3.7/site-packages/sqlalchemy/util/compat.py\", line 178, in raise_\n    raise exception\n  File \"/Users/noah/Otis/backend/service/merchant/merchant-service-venv/lib/python3.7/site-packages/sqlalchemy/pool/base.py\", line 656, in __connect\n    connection = pool._invoke_creator(self)\n  File \"/Users/noah/Otis/backend/service/merchant/merchant-service-venv/lib/python3.7/site-packages/sqlalchemy/engine/strategies.py\", line 114, in connect\n    return dialect.connect(*cargs, **cparams)\n  File \"/Users/noah/Otis/backend/service/merchant/merchant-service-venv/lib/python3.7/site-packages/sqlalchemy/engine/default.py\", line 490, in connect\n    return self.dbapi.connect(*cargs, **cparams)\n  File \"/Users/noah/Otis/backend/service/merchant/merchant-service-venv/lib/python3.7/site-packages/psycopg2/__init__.py\", line 127, in connect\n    conn = _connect(dsn, connection_factory=connection_factory, **kwasync)\npsycopg2.OperationalError: could not translate host name \"otis-db-cluster-1.cluster-c6af70dxq6zw.eu-west-2.rds.amazonaws.com\" to address: nodename nor servname provided, or not known\n\n\nThe above exception was the direct cause of the following exception:\n\nTraceback (most recent call last):\n  File \"/Users/noah/Otis/backend/service/lib/utils/wrappers.py\", line 17, in wrap\n    return_value = func(*args, **kwargs)\n  File \"./impl/__init__.py\", line 41, in GetGeneralMerchant\n    print(Merchant.metadata.create_all(self.db_engine, checkfirst=False))\n  File \"/Users/noah/Otis/backend/service/merchant/merchant-service-venv/lib/python3.7/site-packages/sqlalchemy/sql/schema.py\", line 4465, in create_all\n    ddl.SchemaGenerator, self, checkfirst=checkfirst, tables=tables\n  File \"/Users/noah/Otis/backend/service/merchant/merchant-service-venv/lib/python3.7/site-packages/sqlalchemy/engine/base.py\", line 2103, in _run_visitor\n    with self._optional_conn_ctx_manager(connection) as conn:\n  File \"/usr/local/Cellar/python/3.7.6_1/Frameworks/Python.framework/Versions/3.7/lib/python3.7/contextlib.py\", line 112, in __enter__\n    return next(self.gen)\n  File \"/Users/noah/Otis/backend/service/merchant/merchant-service-venv/lib/python3.7/site-packages/sqlalchemy/engine/base.py\", line 2095, in _optional_conn_ctx_manager\n    with self._contextual_connect() as conn:\n  File \"/Users/noah/Otis/backend/service/merchant/merchant-service-venv/lib/python3.7/site-packages/sqlalchemy/engine/base.py\", line 2311, in _contextual_connect\n    self._wrap_pool_connect(self.pool.connect, None),\n  File \"/Users/noah/Otis/backend/service/merchant/merchant-service-venv/lib/python3.7/site-packages/sqlalchemy/engine/base.py\", line 2349, in _wrap_pool_connect\n    e, dialect, self\n  File \"/Users/noah/Otis/backend/service/merchant/merchant-service-venv/lib/python3.7/site-packages/sqlalchemy/engine/base.py\", line 1591, in _handle_dbapi_exception_noconnection\n    sqlalchemy_exception, with_traceback=exc_info[2], from_=e\n  File \"/Users/noah/Otis/backend/service/merchant/merchant-service-venv/lib/python3.7/site-packages/sqlalchemy/util/compat.py\", line 178, in raise_\n    raise exception\n  File \"/Users/noah/Otis/backend/service/merchant/merchant-service-venv/lib/python3.7/site-packages/sqlalchemy/engine/base.py\", line 2345, in _wrap_pool_connect\n    return fn()\n  File \"/Users/noah/Otis/backend/service/merchant/merchant-service-venv/lib/python3.7/site-packages/sqlalchemy/pool/base.py\", line 364, in connect\n    return _ConnectionFairy._checkout(self)\n  File \"/Users/noah/Otis/backend/service/merchant/merchant-service-venv/lib/python3.7/site-packages/sqlalchemy/pool/base.py\", line 778, in _checkout\n    fairy = _ConnectionRecord.checkout(pool)\n  File \"/Users/noah/Otis/backend/service/merchant/merchant-service-venv/lib/python3.7/site-packages/sqlalchemy/pool/base.py\", line 495, in checkout\n    rec = pool._do_get()\n  File \"/Users/noah/Otis/backend/service/merchant/merchant-service-venv/lib/python3.7/site-packages/sqlalchemy/pool/impl.py\", line 140, in _do_get\n    self._dec_overflow()\n  File \"/Users/noah/Otis/backend/service/merchant/merchant-service-venv/lib/python3.7/site-packages/sqlalchemy/util/langhelpers.py\", line 69, in __exit__\n    exc_value, with_traceback=exc_tb,\n  File \"/Users/noah/Otis/backend/service/merchant/merchant-service-venv/lib/python3.7/site-packages/sqlalchemy/util/compat.py\", line 178, in raise_\n    raise exception\n  File \"/Users/noah/Otis/backend/service/merchant/merchant-service-venv/lib/python3.7/site-packages/sqlalchemy/pool/impl.py\", line 137, in _do_get\n    return self._create_connection()\n  File \"/Users/noah/Otis/backend/service/merchant/merchant-service-venv/lib/python3.7/site-packages/sqlalchemy/pool/base.py\", line 309, in _create_connection\n    return _ConnectionRecord(self)\n  File \"/Users/noah/Otis/backend/service/merchant/merchant-service-venv/lib/python3.7/site-packages/sqlalchemy/pool/base.py\", line 440, in __init__\n    self.__connect(first_connect_check=True)\n  File \"/Users/noah/Otis/backend/service/merchant/merchant-service-venv/lib/python3.7/site-packages/sqlalchemy/pool/base.py\", line 661, in __connect\n    pool.logger.debug(\"Error on connect(): %s\", e)\n  File \"/Users/noah/Otis/backend/service/merchant/merchant-service-venv/lib/python3.7/site-packages/sqlalchemy/util/langhelpers.py\", line 69, in __exit__\n    exc_value, with_traceback=exc_tb,\n  File \"/Users/noah/Otis/backend/service/merchant/merchant-service-venv/lib/python3.7/site-packages/sqlalchemy/util/compat.py\", line 178, in raise_\n    raise exception\n  File \"/Users/noah/Otis/backend/service/merchant/merchant-service-venv/lib/python3.7/site-packages/sqlalchemy/pool/base.py\", line 656, in __connect\n    connection = pool._invoke_creator(self)\n  File \"/Users/noah/Otis/backend/service/merchant/merchant-service-venv/lib/python3.7/site-packages/sqlalchemy/engine/strategies.py\", line 114, in connect\n    return dialect.connect(*cargs, **cparams)\n  File \"/Users/noah/Otis/backend/service/merchant/merchant-service-venv/lib/python3.7/site-packages/sqlalchemy/engine/default.py\", line 490, in connect\n    return self.dbapi.connect(*cargs, **cparams)\n  File \"/Users/noah/Otis/backend/service/merchant/merchant-service-venv/lib/python3.7/site-packages/psycopg2/__init__.py\", line 127, in connect\n    conn = _connect(dsn, connection_factory=connection_factory, **kwasync)\nsqlalchemy.exc.OperationalError: (psycopg2.OperationalError) could not translate host name \"otis-db-cluster-1.cluster-c6af70dxq6zw.eu-west-2.rds.amazonaws.com\" to address: nodename nor servname provided, or not known\n\n(Background on this error at: http://sqlalche.me/e/e3q8)\n"}
{"message": "Error in call to GetGeneralMerchant: OperationalError('(psycopg2.OperationalError) could not translate host name \"otis-db-cluster-1.cluster-c6af70dxq6zw.eu-west-2.rds.amazonaws.com\" to address: nodename nor servname provided, or not known\\n')", "level": "ERROR", "name": "merchant-service", "time": "2020-06-04T17:05:19.050203", "request": "merchantID: \"23034\"\n", "rollbar_uuid": "5140b1c5-4f78-43b8-b2c5-ff318cd6b7f7", "traceback": "Traceback (most recent call last):\n  File \"/Users/noah/Otis/backend/service/merchant/merchant-service-venv/lib/python3.7/site-packages/sqlalchemy/engine/base.py\", line 2345, in _wrap_pool_connect\n    return fn()\n  File \"/Users/noah/Otis/backend/service/merchant/merchant-service-venv/lib/python3.7/site-packages/sqlalchemy/pool/base.py\", line 364, in connect\n    return _ConnectionFairy._checkout(self)\n  File \"/Users/noah/Otis/backend/service/merchant/merchant-service-venv/lib/python3.7/site-packages/sqlalchemy/pool/base.py\", line 778, in _checkout\n    fairy = _ConnectionRecord.checkout(pool)\n  File \"/Users/noah/Otis/backend/service/merchant/merchant-service-venv/lib/python3.7/site-packages/sqlalchemy/pool/base.py\", line 495, in checkout\n    rec = pool._do_get()\n  File \"/Users/noah/Otis/backend/service/merchant/merchant-service-venv/lib/python3.7/site-packages/sqlalchemy/pool/impl.py\", line 140, in _do_get\n    self._dec_overflow()\n  File \"/Users/noah/Otis/backend/service/merchant/merchant-service-venv/lib/python3.7/site-packages/sqlalchemy/util/langhelpers.py\", line 69, in __exit__\n    exc_value, with_traceback=exc_tb,\n  File \"/Users/noah/Otis/backend/service/merchant/merchant-service-venv/lib/python3.7/site-packages/sqlalchemy/util/compat.py\", line 178, in raise_\n    raise exception\n  File \"/Users/noah/Otis/backend/service/merchant/merchant-service-venv/lib/python3.7/site-packages/sqlalchemy/pool/impl.py\", line 137, in _do_get\n    return self._create_connection()\n  File \"/Users/noah/Otis/backend/service/merchant/merchant-service-venv/lib/python3.7/site-packages/sqlalchemy/pool/base.py\", line 309, in _create_connection\n    return _ConnectionRecord(self)\n  File \"/Users/noah/Otis/backend/service/merchant/merchant-service-venv/lib/python3.7/site-packages/sqlalchemy/pool/base.py\", line 440, in __init__\n    self.__connect(first_connect_check=True)\n  File \"/Users/noah/Otis/backend/service/merchant/merchant-service-venv/lib/python3.7/site-packages/sqlalchemy/pool/base.py\", line 661, in __connect\n    pool.logger.debug(\"Error on connect(): %s\", e)\n  File \"/Users/noah/Otis/backend/service/merchant/merchant-service-venv/lib/python3.7/site-packages/sqlalchemy/util/langhelpers.py\", line 69, in __exit__\n    exc_value, with_traceback=exc_tb,\n  File \"/Users/noah/Otis/backend/service/merchant/merchant-service-venv/lib/python3.7/site-packages/sqlalchemy/util/compat.py\", line 178, in raise_\n    raise exception\n  File \"/Users/noah/Otis/backend/service/merchant/merchant-service-venv/lib/python3.7/site-packages/sqlalchemy/pool/base.py\", line 656, in __connect\n    connection = pool._invoke_creator(self)\n  File \"/Users/noah/Otis/backend/service/merchant/merchant-service-venv/lib/python3.7/site-packages/sqlalchemy/engine/strategies.py\", line 114, in connect\n    return dialect.connect(*cargs, **cparams)\n  File \"/Users/noah/Otis/backend/service/merchant/merchant-service-venv/lib/python3.7/site-packages/sqlalchemy/engine/default.py\", line 490, in connect\n    return self.dbapi.connect(*cargs, **cparams)\n  File \"/Users/noah/Otis/backend/service/merchant/merchant-service-venv/lib/python3.7/site-packages/psycopg2/__init__.py\", line 127, in connect\n    conn = _connect(dsn, connection_factory=connection_factory, **kwasync)\npsycopg2.OperationalError: could not translate host name \"otis-db-cluster-1.cluster-c6af70dxq6zw.eu-west-2.rds.amazonaws.com\" to address: nodename nor servname provided, or not known\n\n\nThe above exception was the direct cause of the following exception:\n\nTraceback (most recent call last):\n  File \"/Users/noah/Otis/backend/service/lib/utils/wrappers.py\", line 17, in wrap\n    return_value = func(*args, **kwargs)\n  File \"./impl/__init__.py\", line 41, in GetGeneralMerchant\n    print(Merchant.metadata.create_all(self.db_engine, checkfirst=False))\n  File \"/Users/noah/Otis/backend/service/merchant/merchant-service-venv/lib/python3.7/site-packages/sqlalchemy/sql/schema.py\", line 4465, in create_all\n    ddl.SchemaGenerator, self, checkfirst=checkfirst, tables=tables\n  File \"/Users/noah/Otis/backend/service/merchant/merchant-service-venv/lib/python3.7/site-packages/sqlalchemy/engine/base.py\", line 2103, in _run_visitor\n    with self._optional_conn_ctx_manager(connection) as conn:\n  File \"/usr/local/Cellar/python/3.7.6_1/Frameworks/Python.framework/Versions/3.7/lib/python3.7/contextlib.py\", line 112, in __enter__\n    return next(self.gen)\n  File \"/Users/noah/Otis/backend/service/merchant/merchant-service-venv/lib/python3.7/site-packages/sqlalchemy/engine/base.py\", line 2095, in _optional_conn_ctx_manager\n    with self._contextual_connect() as conn:\n  File \"/Users/noah/Otis/backend/service/merchant/merchant-service-venv/lib/python3.7/site-packages/sqlalchemy/engine/base.py\", line 2311, in _contextual_connect\n    self._wrap_pool_connect(self.pool.connect, None),\n  File \"/Users/noah/Otis/backend/service/merchant/merchant-service-venv/lib/python3.7/site-packages/sqlalchemy/engine/base.py\", line 2349, in _wrap_pool_connect\n    e, dialect, self\n  File \"/Users/noah/Otis/backend/service/merchant/merchant-service-venv/lib/python3.7/site-packages/sqlalchemy/engine/base.py\", line 1591, in _handle_dbapi_exception_noconnection\n    sqlalchemy_exception, with_traceback=exc_info[2], from_=e\n  File \"/Users/noah/Otis/backend/service/merchant/merchant-service-venv/lib/python3.7/site-packages/sqlalchemy/util/compat.py\", line 178, in raise_\n    raise exception\n  File \"/Users/noah/Otis/backend/service/merchant/merchant-service-venv/lib/python3.7/site-packages/sqlalchemy/engine/base.py\", line 2345, in _wrap_pool_connect\n    return fn()\n  File \"/Users/noah/Otis/backend/service/merchant/merchant-service-venv/lib/python3.7/site-packages/sqlalchemy/pool/base.py\", line 364, in connect\n    return _ConnectionFairy._checkout(self)\n  File \"/Users/noah/Otis/backend/service/merchant/merchant-service-venv/lib/python3.7/site-packages/sqlalchemy/pool/base.py\", line 778, in _checkout\n    fairy = _ConnectionRecord.checkout(pool)\n  File \"/Users/noah/Otis/backend/service/merchant/merchant-service-venv/lib/python3.7/site-packages/sqlalchemy/pool/base.py\", line 495, in checkout\n    rec = pool._do_get()\n  File \"/Users/noah/Otis/backend/service/merchant/merchant-service-venv/lib/python3.7/site-packages/sqlalchemy/pool/impl.py\", line 140, in _do_get\n    self._dec_overflow()\n  File \"/Users/noah/Otis/backend/service/merchant/merchant-service-venv/lib/python3.7/site-packages/sqlalchemy/util/langhelpers.py\", line 69, in __exit__\n    exc_value, with_traceback=exc_tb,\n  File \"/Users/noah/Otis/backend/service/merchant/merchant-service-venv/lib/python3.7/site-packages/sqlalchemy/util/compat.py\", line 178, in raise_\n    raise exception\n  File \"/Users/noah/Otis/backend/service/merchant/merchant-service-venv/lib/python3.7/site-packages/sqlalchemy/pool/impl.py\", line 137, in _do_get\n    return self._create_connection()\n  File \"/Users/noah/Otis/backend/service/merchant/merchant-service-venv/lib/python3.7/site-packages/sqlalchemy/pool/base.py\", line 309, in _create_connection\n    return _ConnectionRecord(self)\n  File \"/Users/noah/Otis/backend/service/merchant/merchant-service-venv/lib/python3.7/site-packages/sqlalchemy/pool/base.py\", line 440, in __init__\n    self.__connect(first_connect_check=True)\n  File \"/Users/noah/Otis/backend/service/merchant/merchant-service-venv/lib/python3.7/site-packages/sqlalchemy/pool/base.py\", line 661, in __connect\n    pool.logger.debug(\"Error on connect(): %s\", e)\n  File \"/Users/noah/Otis/backend/service/merchant/merchant-service-venv/lib/python3.7/site-packages/sqlalchemy/util/langhelpers.py\", line 69, in __exit__\n    exc_value, with_traceback=exc_tb,\n  File \"/Users/noah/Otis/backend/service/merchant/merchant-service-venv/lib/python3.7/site-packages/sqlalchemy/util/compat.py\", line 178, in raise_\n    raise exception\n  File \"/Users/noah/Otis/backend/service/merchant/merchant-service-venv/lib/python3.7/site-packages/sqlalchemy/pool/base.py\", line 656, in __connect\n    connection = pool._invoke_creator(self)\n  File \"/Users/noah/Otis/backend/service/merchant/merchant-service-venv/lib/python3.7/site-packages/sqlalchemy/engine/strategies.py\", line 114, in connect\n    return dialect.connect(*cargs, **cparams)\n  File \"/Users/noah/Otis/backend/service/merchant/merchant-service-venv/lib/python3.7/site-packages/sqlalchemy/engine/default.py\", line 490, in connect\n    return self.dbapi.connect(*cargs, **cparams)\n  File \"/Users/noah/Otis/backend/service/merchant/merchant-service-venv/lib/python3.7/site-packages/psycopg2/__init__.py\", line 127, in connect\n    conn = _connect(dsn, connection_factory=connection_factory, **kwasync)\nsqlalchemy.exc.OperationalError: (psycopg2.OperationalError) could not translate host name \"otis-db-cluster-1.cluster-c6af70dxq6zw.eu-west-2.rds.amazonaws.com\" to address: nodename nor servname provided, or not known\n\n(Background on this error at: http://sqlalche.me/e/e3q8)\n"}
{"message": "Error in call to GetGeneralMerchant: OperationalError('(psycopg2.OperationalError) could not translate host name \"otis-db-cluster-1.cluster-c6af70dxq6zw.eu-west-2.rds.amazonaws.com\" to address: nodename nor servname provided, or not known\\n')", "level": "ERROR", "name": "merchant-service", "time": "2020-06-04T17:14:42.393785", "request": "merchantID: \"23034\"\n", "rollbar_uuid": "11c83a28-bc93-4ad2-bf2b-703010e61238", "traceback": "Traceback (most recent call last):\n  File \"/Users/noah/Otis/backend/service/merchant/merchant-service-venv/lib/python3.7/site-packages/sqlalchemy/engine/base.py\", line 2345, in _wrap_pool_connect\n    return fn()\n  File \"/Users/noah/Otis/backend/service/merchant/merchant-service-venv/lib/python3.7/site-packages/sqlalchemy/pool/base.py\", line 364, in connect\n    return _ConnectionFairy._checkout(self)\n  File \"/Users/noah/Otis/backend/service/merchant/merchant-service-venv/lib/python3.7/site-packages/sqlalchemy/pool/base.py\", line 778, in _checkout\n    fairy = _ConnectionRecord.checkout(pool)\n  File \"/Users/noah/Otis/backend/service/merchant/merchant-service-venv/lib/python3.7/site-packages/sqlalchemy/pool/base.py\", line 495, in checkout\n    rec = pool._do_get()\n  File \"/Users/noah/Otis/backend/service/merchant/merchant-service-venv/lib/python3.7/site-packages/sqlalchemy/pool/impl.py\", line 140, in _do_get\n    self._dec_overflow()\n  File \"/Users/noah/Otis/backend/service/merchant/merchant-service-venv/lib/python3.7/site-packages/sqlalchemy/util/langhelpers.py\", line 69, in __exit__\n    exc_value, with_traceback=exc_tb,\n  File \"/Users/noah/Otis/backend/service/merchant/merchant-service-venv/lib/python3.7/site-packages/sqlalchemy/util/compat.py\", line 178, in raise_\n    raise exception\n  File \"/Users/noah/Otis/backend/service/merchant/merchant-service-venv/lib/python3.7/site-packages/sqlalchemy/pool/impl.py\", line 137, in _do_get\n    return self._create_connection()\n  File \"/Users/noah/Otis/backend/service/merchant/merchant-service-venv/lib/python3.7/site-packages/sqlalchemy/pool/base.py\", line 309, in _create_connection\n    return _ConnectionRecord(self)\n  File \"/Users/noah/Otis/backend/service/merchant/merchant-service-venv/lib/python3.7/site-packages/sqlalchemy/pool/base.py\", line 440, in __init__\n    self.__connect(first_connect_check=True)\n  File \"/Users/noah/Otis/backend/service/merchant/merchant-service-venv/lib/python3.7/site-packages/sqlalchemy/pool/base.py\", line 661, in __connect\n    pool.logger.debug(\"Error on connect(): %s\", e)\n  File \"/Users/noah/Otis/backend/service/merchant/merchant-service-venv/lib/python3.7/site-packages/sqlalchemy/util/langhelpers.py\", line 69, in __exit__\n    exc_value, with_traceback=exc_tb,\n  File \"/Users/noah/Otis/backend/service/merchant/merchant-service-venv/lib/python3.7/site-packages/sqlalchemy/util/compat.py\", line 178, in raise_\n    raise exception\n  File \"/Users/noah/Otis/backend/service/merchant/merchant-service-venv/lib/python3.7/site-packages/sqlalchemy/pool/base.py\", line 656, in __connect\n    connection = pool._invoke_creator(self)\n  File \"/Users/noah/Otis/backend/service/merchant/merchant-service-venv/lib/python3.7/site-packages/sqlalchemy/engine/strategies.py\", line 114, in connect\n    return dialect.connect(*cargs, **cparams)\n  File \"/Users/noah/Otis/backend/service/merchant/merchant-service-venv/lib/python3.7/site-packages/sqlalchemy/engine/default.py\", line 490, in connect\n    return self.dbapi.connect(*cargs, **cparams)\n  File \"/Users/noah/Otis/backend/service/merchant/merchant-service-venv/lib/python3.7/site-packages/psycopg2/__init__.py\", line 127, in connect\n    conn = _connect(dsn, connection_factory=connection_factory, **kwasync)\npsycopg2.OperationalError: could not translate host name \"otis-db-cluster-1.cluster-c6af70dxq6zw.eu-west-2.rds.amazonaws.com\" to address: nodename nor servname provided, or not known\n\n\nThe above exception was the direct cause of the following exception:\n\nTraceback (most recent call last):\n  File \"/Users/noah/Otis/backend/service/lib/utils/wrappers.py\", line 17, in wrap\n    return_value = func(*args, **kwargs)\n  File \"./impl/__init__.py\", line 41, in GetGeneralMerchant\n    print(Merchant.metadata.create_all(self.db_engine, checkfirst=False))\n  File \"/Users/noah/Otis/backend/service/merchant/merchant-service-venv/lib/python3.7/site-packages/sqlalchemy/sql/schema.py\", line 4465, in create_all\n    ddl.SchemaGenerator, self, checkfirst=checkfirst, tables=tables\n  File \"/Users/noah/Otis/backend/service/merchant/merchant-service-venv/lib/python3.7/site-packages/sqlalchemy/engine/base.py\", line 2103, in _run_visitor\n    with self._optional_conn_ctx_manager(connection) as conn:\n  File \"/usr/local/Cellar/python/3.7.6_1/Frameworks/Python.framework/Versions/3.7/lib/python3.7/contextlib.py\", line 112, in __enter__\n    return next(self.gen)\n  File \"/Users/noah/Otis/backend/service/merchant/merchant-service-venv/lib/python3.7/site-packages/sqlalchemy/engine/base.py\", line 2095, in _optional_conn_ctx_manager\n    with self._contextual_connect() as conn:\n  File \"/Users/noah/Otis/backend/service/merchant/merchant-service-venv/lib/python3.7/site-packages/sqlalchemy/engine/base.py\", line 2311, in _contextual_connect\n    self._wrap_pool_connect(self.pool.connect, None),\n  File \"/Users/noah/Otis/backend/service/merchant/merchant-service-venv/lib/python3.7/site-packages/sqlalchemy/engine/base.py\", line 2349, in _wrap_pool_connect\n    e, dialect, self\n  File \"/Users/noah/Otis/backend/service/merchant/merchant-service-venv/lib/python3.7/site-packages/sqlalchemy/engine/base.py\", line 1591, in _handle_dbapi_exception_noconnection\n    sqlalchemy_exception, with_traceback=exc_info[2], from_=e\n  File \"/Users/noah/Otis/backend/service/merchant/merchant-service-venv/lib/python3.7/site-packages/sqlalchemy/util/compat.py\", line 178, in raise_\n    raise exception\n  File \"/Users/noah/Otis/backend/service/merchant/merchant-service-venv/lib/python3.7/site-packages/sqlalchemy/engine/base.py\", line 2345, in _wrap_pool_connect\n    return fn()\n  File \"/Users/noah/Otis/backend/service/merchant/merchant-service-venv/lib/python3.7/site-packages/sqlalchemy/pool/base.py\", line 364, in connect\n    return _ConnectionFairy._checkout(self)\n  File \"/Users/noah/Otis/backend/service/merchant/merchant-service-venv/lib/python3.7/site-packages/sqlalchemy/pool/base.py\", line 778, in _checkout\n    fairy = _ConnectionRecord.checkout(pool)\n  File \"/Users/noah/Otis/backend/service/merchant/merchant-service-venv/lib/python3.7/site-packages/sqlalchemy/pool/base.py\", line 495, in checkout\n    rec = pool._do_get()\n  File \"/Users/noah/Otis/backend/service/merchant/merchant-service-venv/lib/python3.7/site-packages/sqlalchemy/pool/impl.py\", line 140, in _do_get\n    self._dec_overflow()\n  File \"/Users/noah/Otis/backend/service/merchant/merchant-service-venv/lib/python3.7/site-packages/sqlalchemy/util/langhelpers.py\", line 69, in __exit__\n    exc_value, with_traceback=exc_tb,\n  File \"/Users/noah/Otis/backend/service/merchant/merchant-service-venv/lib/python3.7/site-packages/sqlalchemy/util/compat.py\", line 178, in raise_\n    raise exception\n  File \"/Users/noah/Otis/backend/service/merchant/merchant-service-venv/lib/python3.7/site-packages/sqlalchemy/pool/impl.py\", line 137, in _do_get\n    return self._create_connection()\n  File \"/Users/noah/Otis/backend/service/merchant/merchant-service-venv/lib/python3.7/site-packages/sqlalchemy/pool/base.py\", line 309, in _create_connection\n    return _ConnectionRecord(self)\n  File \"/Users/noah/Otis/backend/service/merchant/merchant-service-venv/lib/python3.7/site-packages/sqlalchemy/pool/base.py\", line 440, in __init__\n    self.__connect(first_connect_check=True)\n  File \"/Users/noah/Otis/backend/service/merchant/merchant-service-venv/lib/python3.7/site-packages/sqlalchemy/pool/base.py\", line 661, in __connect\n    pool.logger.debug(\"Error on connect(): %s\", e)\n  File \"/Users/noah/Otis/backend/service/merchant/merchant-service-venv/lib/python3.7/site-packages/sqlalchemy/util/langhelpers.py\", line 69, in __exit__\n    exc_value, with_traceback=exc_tb,\n  File \"/Users/noah/Otis/backend/service/merchant/merchant-service-venv/lib/python3.7/site-packages/sqlalchemy/util/compat.py\", line 178, in raise_\n    raise exception\n  File \"/Users/noah/Otis/backend/service/merchant/merchant-service-venv/lib/python3.7/site-packages/sqlalchemy/pool/base.py\", line 656, in __connect\n    connection = pool._invoke_creator(self)\n  File \"/Users/noah/Otis/backend/service/merchant/merchant-service-venv/lib/python3.7/site-packages/sqlalchemy/engine/strategies.py\", line 114, in connect\n    return dialect.connect(*cargs, **cparams)\n  File \"/Users/noah/Otis/backend/service/merchant/merchant-service-venv/lib/python3.7/site-packages/sqlalchemy/engine/default.py\", line 490, in connect\n    return self.dbapi.connect(*cargs, **cparams)\n  File \"/Users/noah/Otis/backend/service/merchant/merchant-service-venv/lib/python3.7/site-packages/psycopg2/__init__.py\", line 127, in connect\n    conn = _connect(dsn, connection_factory=connection_factory, **kwasync)\nsqlalchemy.exc.OperationalError: (psycopg2.OperationalError) could not translate host name \"otis-db-cluster-1.cluster-c6af70dxq6zw.eu-west-2.rds.amazonaws.com\" to address: nodename nor servname provided, or not known\n\n(Background on this error at: http://sqlalche.me/e/e3q8)\n"}
